<?xml version="1.0" ?>
<robot name="kinectbot" xmlns:xacro="http://www.ros.org/wiki/xacro">

<xacro:include filename="$(find kinectbot_description)/urdf/materials.xacro" />
<!-- <xacro:include filename="$(find kinectbot_description)/urdf/kinectbot.trans" /> -->
<xacro:include filename="$(find kinectbot_description)/gazebo/kinectbot_materials.gazebo" />
<xacro:include filename="$(find kinectbot_description)/gazebo/kinectbot_plugins.gazebo" />
<xacro:include filename="$(find kinectbot_description)/gazebo/kinectbot_physics.gazebo" />

<link name="base_link">
  <inertial>
    <origin rpy="0 0 0" xyz="0.0 6.126832052068927e-15 0.03551931309841485"/>
    <mass value="0.28304512232760054"/>
    <inertia ixx="0.001756" ixy="0.0" ixz="0.0" iyy="0.000924" iyz="-0.0" izz="0.002629"/>
  </inertial>
  <visual>
    <origin rpy="0 0 0" xyz="0 0 0"/>
    <geometry>
      <mesh filename="package://kinectbot_description/meshes/base_link.stl" scale="0.001 0.001 0.001"/>
    </geometry>
    <material name="silver"/>
  </visual>
  <collision>
    <origin rpy="0 0 0" xyz="0 0 0"/>
    <geometry>
      <mesh filename="package://kinectbot_description/meshes/base_link.stl" scale="0.001 0.001 0.001"/>
    </geometry>
  </collision>
</link>

<link name="motor_left_1">
  <inertial>
    <origin rpy="0 0 0" xyz="0.02352734922861146 9.900213718158758e-15 2.0816681711721685e-17"/>
    <mass value="0.026610672076673177"/>
    <inertia ixx="2e-06" ixy="0.0" ixz="-0.0" iyy="6e-06" iyz="-0.0" izz="6e-06"/>
  </inertial>
  <visual>
    <origin rpy="0 0 0" xyz="0.075 -0.0 -0.05005"/>
    <geometry>
      <mesh filename="package://kinectbot_description/meshes/motor_left_1.stl" scale="0.001 0.001 0.001"/>
    </geometry>
    <material name="silver"/>
  </visual>
  <collision>
    <origin rpy="0 0 0" xyz="0.075 -0.0 -0.05005"/>
    <geometry>
      <mesh filename="package://kinectbot_description/meshes/motor_left_1.stl" scale="0.001 0.001 0.001"/>
    </geometry>
  </collision>
</link>

<link name="motor_right_1">
  <inertial>
    <origin rpy="0 0 0" xyz="-0.023527349228611473 -9.900213718158753e-15 0.0"/>
    <mass value="0.02661067207667319"/>
    <inertia ixx="2e-06" ixy="0.0" ixz="-0.0" iyy="6e-06" iyz="0.0" izz="6e-06"/>
  </inertial>
  <visual>
    <origin rpy="0 0 0" xyz="-0.075 -0.0 -0.05005"/>
    <geometry>
      <mesh filename="package://kinectbot_description/meshes/motor_right_1.stl" scale="0.001 0.001 0.001"/>
    </geometry>
    <material name="silver"/>
  </visual>
  <collision>
    <origin rpy="0 0 0" xyz="-0.075 -0.0 -0.05005"/>
    <geometry>
      <mesh filename="package://kinectbot_description/meshes/motor_right_1.stl" scale="0.001 0.001 0.001"/>
    </geometry>
  </collision>
</link>

<link name="wheel_right_1">
  <inertial>
    <origin rpy="0 0 0" xyz="0.022499999999999992 -1.1500351399691738e-15 2.7755575615628914e-17"/>
    <mass value="0.3275058505088574"/>
    <inertia ixx="0.000411" ixy="-0.0" ixz="0.0" iyy="0.000261" iyz="-0.0" izz="0.000261"/>
  </inertial>
  <visual>
    <origin rpy="0 0 0" xyz="-0.08 0.0 -0.05005"/>
    <geometry>
      <mesh filename="package://kinectbot_description/meshes/wheel_right_1.stl" scale="0.001 0.001 0.001"/>
    </geometry>
    <material name="silver"/>
  </visual>
  <collision>
    <origin rpy="0 0 0" xyz="-0.08 0.0 -0.05005"/>
    <geometry>
      <mesh filename="package://kinectbot_description/meshes/wheel_right_1.stl" scale="0.001 0.001 0.001"/>
    </geometry>
  </collision>
</link>

<link name="wheel_left_1">
  <inertial>
    <origin rpy="0 0 0" xyz="-0.022500000000000075 1.1446193712846546e-15 6.245004513516506e-17"/>
    <mass value="0.32750585050885755"/>
    <inertia ixx="0.000411" ixy="-0.0" ixz="0.0" iyy="0.000261" iyz="-0.0" izz="0.000261"/>
  </inertial>
  <visual>
    <origin rpy="0 0 0" xyz="0.08 -0.0 -0.05005"/>
    <geometry>
      <mesh filename="package://kinectbot_description/meshes/wheel_left_1.stl" scale="0.001 0.001 0.001"/>
    </geometry>
    <material name="silver"/>
  </visual>
  <collision>
    <origin rpy="0 0 0" xyz="0.08 -0.0 -0.05005"/>
    <geometry>
      <mesh filename="package://kinectbot_description/meshes/wheel_left_1.stl" scale="0.001 0.001 0.001"/>
    </geometry>
  </collision>
</link>

<link name="castor_rear_1">
  <inertial>
    <origin rpy="0 0 0" xyz="5.0260617188559307e-17 0.0 -0.012749999999999945"/>
    <mass value="0.02099369290761378"/>
    <inertia ixx="2e-06" ixy="-0.0" ixz="-0.0" iyy="2e-06" iyz="-0.0" izz="2e-06"/>
  </inertial>
  <visual>
    <origin rpy="0 0 0" xyz="-0.0 0.115 -0.03"/>
    <geometry>
      <mesh filename="package://kinectbot_description/meshes/castor_rear_1.stl" scale="0.001 0.001 0.001"/>
    </geometry>
    <material name="silver"/>
  </visual>
  <collision>
    <origin rpy="0 0 0" xyz="-0.0 0.115 -0.03"/>
    <geometry>
      <mesh filename="package://kinectbot_description/meshes/castor_rear_1.stl" scale="0.001 0.001 0.001"/>
    </geometry>
  </collision>
</link>

<link name="castor_front_1">
  <inertial>
    <origin rpy="0 0 0" xyz="5.0260617188559307e-17 0.0 -0.012749999999999945"/>
    <mass value="0.02099369290761378"/>
    <inertia ixx="2e-06" ixy="-0.0" ixz="-0.0" iyy="2e-06" iyz="0.0" izz="2e-06"/>
  </inertial>
  <visual>
    <origin rpy="0 0 0" xyz="-0.0 -0.115 -0.03"/>
    <geometry>
      <mesh filename="package://kinectbot_description/meshes/castor_front_1.stl" scale="0.001 0.001 0.001"/>
    </geometry>
    <material name="silver"/>
  </visual>
  <collision>
    <origin rpy="0 0 0" xyz="-0.0 -0.115 -0.03"/>
    <geometry>
      <mesh filename="package://kinectbot_description/meshes/castor_front_1.stl" scale="0.001 0.001 0.001"/>
    </geometry>
  </collision>
</link>

<link name="bolt_2_1">
  <inertial>
    <origin rpy="0 0 0" xyz="-1.3877787807814457e-17 1.3877787807814457e-17 0.06250000000000001"/>
    <mass value="0.004198738581522751"/>
    <inertia ixx="5e-06" ixy="0.0" ixz="0.0" iyy="5e-06" iyz="0.0" izz="0.0"/>
  </inertial>
  <visual>
    <origin rpy="0 0 0" xyz="-0.05 -0.075 -0.034"/>
    <geometry>
      <mesh filename="package://kinectbot_description/meshes/bolt_2_1.stl" scale="0.001 0.001 0.001"/>
    </geometry>
    <material name="silver"/>
  </visual>
  <collision>
    <origin rpy="0 0 0" xyz="-0.05 -0.075 -0.034"/>
    <geometry>
      <mesh filename="package://kinectbot_description/meshes/bolt_2_1.stl" scale="0.001 0.001 0.001"/>
    </geometry>
  </collision>
</link>

<link name="bolt_4_1">
  <inertial>
    <origin rpy="0 0 0" xyz="1.3877787807814457e-17 1.3877787807814457e-17 0.06250000000000001"/>
    <mass value="0.004198738581522751"/>
    <inertia ixx="5e-06" ixy="-0.0" ixz="0.0" iyy="5e-06" iyz="0.0" izz="0.0"/>
  </inertial>
  <visual>
    <origin rpy="0 0 0" xyz="0.05 -0.075 -0.034"/>
    <geometry>
      <mesh filename="package://kinectbot_description/meshes/bolt_4_1.stl" scale="0.001 0.001 0.001"/>
    </geometry>
    <material name="silver"/>
  </visual>
  <collision>
    <origin rpy="0 0 0" xyz="0.05 -0.075 -0.034"/>
    <geometry>
      <mesh filename="package://kinectbot_description/meshes/bolt_4_1.stl" scale="0.001 0.001 0.001"/>
    </geometry>
  </collision>
</link>

<link name="bolt_3_1">
  <inertial>
    <origin rpy="0 0 0" xyz="1.3877787807814457e-17 -2.7755575615628914e-17 0.06250000000000001"/>
    <mass value="0.004198738581522751"/>
    <inertia ixx="5e-06" ixy="-0.0" ixz="0.0" iyy="5e-06" iyz="-0.0" izz="0.0"/>
  </inertial>
  <visual>
    <origin rpy="0 0 0" xyz="0.05 0.075 -0.034"/>
    <geometry>
      <mesh filename="package://kinectbot_description/meshes/bolt_3_1.stl" scale="0.001 0.001 0.001"/>
    </geometry>
    <material name="silver"/>
  </visual>
  <collision>
    <origin rpy="0 0 0" xyz="0.05 0.075 -0.034"/>
    <geometry>
      <mesh filename="package://kinectbot_description/meshes/bolt_3_1.stl" scale="0.001 0.001 0.001"/>
    </geometry>
  </collision>
</link>

<link name="bolt_1_1">
  <inertial>
    <origin rpy="0 0 0" xyz="-1.3877787807814457e-17 -2.7755575615628914e-17 0.06250000000000001"/>
    <mass value="0.004198738581522751"/>
    <inertia ixx="5e-06" ixy="-0.0" ixz="0.0" iyy="5e-06" iyz="-0.0" izz="0.0"/>
  </inertial>
  <visual>
    <origin rpy="0 0 0" xyz="-0.05 0.075 -0.034"/>
    <geometry>
      <mesh filename="package://kinectbot_description/meshes/bolt_1_1.stl" scale="0.001 0.001 0.001"/>
    </geometry>
    <material name="silver"/>
  </visual>
  <collision>
    <origin rpy="0 0 0" xyz="-0.05 0.075 -0.034"/>
    <geometry>
      <mesh filename="package://kinectbot_description/meshes/bolt_1_1.stl" scale="0.001 0.001 0.001"/>
    </geometry>
  </collision>
</link>

<link name="mid_plate_1">
  <inertial>
    <origin rpy="0 0 0" xyz="-0.050021232975208656 -0.08003397276033417 0.0020000000000000018"/>
    <mass value="0.31639380088590274"/>
    <inertia ixx="0.001867" ixy="1e-06" ixz="-0.0" iyy="0.00152" iyz="0.0" izz="0.003386"/>
  </inertial>
  <visual>
    <origin rpy="0 0 0" xyz="-0.05 -0.075 -0.159"/>
    <geometry>
      <mesh filename="package://kinectbot_description/meshes/mid_plate_1.stl" scale="0.001 0.001 0.001"/>
    </geometry>
    <material name="silver"/>
  </visual>
  <collision>
    <origin rpy="0 0 0" xyz="-0.05 -0.075 -0.159"/>
    <geometry>
      <mesh filename="package://kinectbot_description/meshes/mid_plate_1.stl" scale="0.001 0.001 0.001"/>
    </geometry>
  </collision>
</link>

<link name="kinect_1">
  <inertial>
    <origin rpy="0 0 0" xyz="-0.0003153296233320502 -0.00012448819169019743 0.027636453446634818"/>
    <mass value="0.3185446036288292"/>
    <inertia ixx="9.4e-05" ixy="-0.0" ixz="0.0" iyy="0.000806" iyz="0.0" izz="0.000821"/>
  </inertial>
  <visual>
    <origin rpy="0 0 0" xyz="-0.0 0.055 -0.163"/>
    <geometry>
      <mesh filename="package://kinectbot_description/meshes/kinect_1.stl" scale="0.001 0.001 0.001"/>
    </geometry>
    <material name="silver"/>
  </visual>
  <collision>
    <origin rpy="0 0 0" xyz="-0.0 0.055 -0.163"/>
    <geometry>
      <mesh filename="package://kinectbot_description/meshes/kinect_1.stl" scale="0.001 0.001 0.001"/>
    </geometry>
  </collision>
</link>

<joint name="Rigid1" type="fixed">
  <origin rpy="0 0 0" xyz="-0.075 0.0 0.05005"/>
  <parent link="base_link"/>
  <child link="motor_left_1"/>
</joint>

<joint name="Rigid2" type="fixed">
  <origin rpy="0 0 0" xyz="0.075 0.0 0.05005"/>
  <parent link="base_link"/>
  <child link="motor_right_1"/>
</joint>

<joint name="Rev3" type="continuous">
  <origin rpy="0 0 0" xyz="0.005 0.0 0.0"/>
  <parent link="motor_right_1"/>
  <child link="wheel_right_1"/>
  <axis xyz="1.0 0.0 0.0"/>
</joint>

<joint name="Rev4" type="continuous">
  <origin rpy="0 0 0" xyz="-0.005 0.0 0.0"/>
  <parent link="motor_left_1"/>
  <child link="wheel_left_1"/>
  <axis xyz="1.0 0.0 0.0"/>
</joint>

<joint name="Rigid5" type="fixed">
  <origin rpy="0 0 0" xyz="0.0 -0.115 0.03"/>
  <parent link="base_link"/>
  <child link="castor_rear_1"/>
</joint>

<joint name="Rigid6" type="fixed">
  <origin rpy="0 0 0" xyz="0.0 0.115 0.03"/>
  <parent link="base_link"/>
  <child link="castor_front_1"/>
</joint>

<joint name="Rigid8" type="fixed">
  <origin rpy="0 0 0" xyz="0.05 0.075 0.034"/>
  <parent link="base_link"/>
  <child link="bolt_2_1"/>
</joint>

<joint name="Rigid9" type="fixed">
  <origin rpy="0 0 0" xyz="-0.05 0.075 0.034"/>
  <parent link="base_link"/>
  <child link="bolt_4_1"/>
</joint>

<joint name="Rigid10" type="fixed">
  <origin rpy="0 0 0" xyz="-0.05 -0.075 0.034"/>
  <parent link="base_link"/>
  <child link="bolt_3_1"/>
</joint>

<joint name="Rigid11" type="fixed">
  <origin rpy="0 0 0" xyz="0.05 -0.075 0.034"/>
  <parent link="base_link"/>
  <child link="bolt_1_1"/>
</joint>

<joint name="Rigid12" type="fixed">
  <origin rpy="0 0 0" xyz="0.0 0.0 0.125"/>
  <parent link="bolt_2_1"/>
  <child link="mid_plate_1"/>
</joint>

<joint name="Rigid13" type="fixed">
  <origin rpy="0 0 0" xyz="-0.05 -0.13 0.004"/>
  <parent link="mid_plate_1"/>
  <child link="kinect_1"/>
</joint>

</robot>
